Workbook

Sheet รายแปลง
A2: สายงาน | B2: ไร่ | C2: ลำดับ | D2: รหัสโควต้า | E2: รหัสแปลง | F2: เลขแปลง | G2: รหัสแปลง | H2: พื้นที่หมุนเวียน | I2: พักดิน68/69 | J2: พื้นที่อ้อย | K2: ประเภทอ้อย | L2: ประเภท2 | M2: พันธุ์อ้อย | N2: น้ำ | O2: จำนวนครั้ง | P2: แหล่งน้ำ | Q2: ปริมาตรในสระ | R2: แหล่งเติมน้ำ | S2: ต้นกำลัง | T2: ประเภทให้น้ำ | U2: เกรดน้ำ100% | V2: ให้น้ำ | W2: คาดฯใช้น้ำ | X2: ชื่อผู้รับเหมา | Y2: ชุด | Z2: ให้น้ำ (ไร่) | AA2: อุปกรณ์ผู้รับเหมา | AB2: อุปกรณ์ | AC2: ร่อง | AD2: ระยะร่อง | AE2: ดิน
A3: 1 | B3: กระทุ่ม 1 | C3: 1 | D3: 902 | E3: 634 | F3: 101 | G3: 902101 | H3: 15.78 | J3: 15.78 | K3: อ้อยตอ 1 | L3: อ้อยตอ | M3: CSB15-221 | N3: Fully | O3: 6 | P3: สระ 902301 | Q3: 85000 | R3: น้ำฝน | S3: เครื่องยนต์สูบน้ำ/Solar Mobile | T3: น้ำหยดบนดิน Fix | U3: Fully | V3: 6 | W3: 4734 | X3: กษมา1 | Z3: 15.78 | AA3: อุปกรณ์ผู้รับเหมา | AC3: เดี่ยว | AD3: 1.85 | AE3: เหนียว
A4: 1 | B4: กระทุ่ม 1 | C4: 2 | D4: 902 | E4: 639 | F4: 102 | G4: 902102 | H4: 8.37 | I4: 8.37 | K4: พักดิน | L4: พักดิน | M4: KK-3 | N4: sup | O4: 3 | P4: สระ 902301 | Q4: 85000 | R4: น้ำฝน | S4: เครื่องยนต์สูบน้ำ/Solar Mobile | T4: น้ำหยดบนดิน Fix | U4: Fully | V4: 6 | W4: 0 | X4: กษมา | Z4: 8.37 | AA4: อุปกรณ์ของผู้รับเหมา | AC4: เดี่ยว | AD4: 1.85 | AE4: เหนียว
A5: 1 | B5: กระทุ่ม 1 | C5: 3 | D5: 902 | E5: 635 | F5: 103 | G5: 902103 | H5: 15.84 | J5: 15.84 | K5: อ้อยตอ 1 | L5: อ้อยตอ | M5: MPT12-358 | N5: Fully | O5: 6 | P5: สระ 902301 | Q5: 85000 | R5: น้ำฝน | S5: เครื่องยนต์สูบน้ำ/Solar Mobile | T5: น้ำหยดบนดิน Fix | U5: Fully | V5: 6 | W5: 4752 | X5: กษมา2 | Z5: 15.84 | AA5: อุปกรณ์ผู้รับเหมา | AC5: คู่ | AD5: 1.85 | AE5: เหนียว
A6: 1 | B6: กระทุ่ม 1 | C6: 4 | D6: 902 | E6: 632 | F6: 104 | G6: 902104 | H6: 21.91 | I6: 21.91 | K6: พักดิน | L6: พักดิน | M6: MPT-618 | N6: Fully | O6: 6 | P6: สระ 902301 | Q6: 85000 | R6: น้ำฝน | S6: เครื่องยนต์สูบน้ำ/Solar Mobile | T6: น้ำหยดบนดิน Fix | U6: Fully | V6: 6 | W6: 0 | X6: กษมา3 | Z6: 21.91 | AA6: อุปกรณ์ผู้รับเหมา | AC6: คู่ | AD6: 1.85 | AE6: เหนียว
A7: 1 | B7: กระทุ่ม 1 | C7: 5 | D7: 902 | E7: 618 | F7: 105 | G7: 902105 | H7: 61.2 | J7: 61.2 | K7: อ้อยตอ 1 | L7: อ้อยตอ | M7: KK-3 | N7: Fully | O7: 6 | P7: สระ 902302 | Q7: 590000 | R7: น้ำฝน | S7: เครื่องยนต์สุบน้ำ | T7: น้ำหยดบนดิน Move | U7: sup | V7: 3 | W7: 9180 | X7: กษมา1 | Z7: 68.81 | AA7: อุปกรณ์ผู้รับเหมา | AC7: เดี่ยว | AD7: 1.85 | AE7: เหนียว
A8: 1 | B8: กระทุ่ม 1 | C8: 6 | D8: 902 | E8: 620 | F8: 106 | G8: 902106 | H8: 80.7 | J8: 80.7 | K8: อ้อยตอ 2 | L8: อ้อยตอ | M8: ทองภูมิ 6 | N8: Fully | O8: 6 | P8: สระ 902302 | Q8: 590000 | R8: น้ำฝน | S8: เครื่องยนต์สูบน้ำ/โรงสูบน้ำ Solar Cell | T8: น้ำหยด 3/ราดร่อง | U8: Fully | V8: 16 | W8: 64560 | X8: กษมา | Z8: 86.07 | AA8: อุปกรณ์ผู้รับเหมา | AC8: คู่ | AD8: 1.85 | AE8: เหนียว
A9: 1 | B9: กระทุ่ม 1 | C9: 7 | D9: 902 | E9: 612 | F9: 107 | G9: 902107 | H9: 13.21 | I9: 13.21 | K9: พักดิน | L9: พักดิน | M9: MPT-442 | N9: Fully | O9: 6 | P9: สระ 902302 | Q9: 590000 | R9: น้ำฝน | S9: เครื่องยนต์/โรงสูบน้ำ Solar Cell | T9: น้ำหยด 3/ราดร่อง | U9: Fully | V9: 16 | W9: 0 | X9: กษมา | Z9: 14.52 | AA9: อุปกรณ์ผู้รับเหมา | AC9: คู่ | AD9: 1.85 | AE9: เหนียว
A10: 1 | B10: กระทุ่ม 1 | C10: 8 | D10: 902 | E10: 613 | F10: 108 | G10: 902108 | H10: 29.56 | I10: 29.56 | K10: พักดิน | L10: พักดิน | M10: MPT-442 | N10: Fully | O10: 6 | P10: สระ 902302 | Q10: 590000 | R10: น้ำฝน | S10: เครื่องยนต์/โรงสูบน้ำ Solar Cell | T10: น้ำหยด 3/ราดร่อง | U10: Fully | V10: 16 | W10: 0 | X10: กษมา | Z10: 30.72 | AA10: อุปกรณ์ผู้รับเหมา | AC10: คู่ | AD10: 1.85 | AE10: เหนียว
A11: 1 | B11: กระทุ่ม 1 | C11: 9 | D11: 902 | E11: 614 | F11: 109 | G11: 902109 | H11: 28.46 | I11: 28.46 | K11: พักดิน | L11: พักดิน | M11: MTP-618 | N11: Fully | O11: 6 | P11: สระ 902302 | Q11: 590000 | R11: น้ำฝน | S11: เครื่องยนต์/โรงสูบน้ำ Solar Cell | T11: น้ำหยด 3/ราดร่อง | U11: Fully | V11: 16 | W11: 0 | X11: กษมา | Z11: 30.35 | AA11: อุปกรณ์ผู้รับเหมา | AC11: คู่ | AD11: 1.85 | AE11: เหนียว
A12: 1 | B12: กระทุ่ม 1 | C12: 10 | D12: 902 | E12: 617/1 | F12: 110 | G12: 902110 | H12: 18.21 | J12: 18.21 | K12: อ้อยตอ 1 | L12: อ้อยตอ | M12: Csb08-108 | N12: Fully | O12: 6 | P12: สระ 902302 | Q12: 590000 | R12: น้ำฝน | S12: เครื่องยนต์สูบน้ำ/โรงสูบน้ำ Solar Cell | T12: น้ำหยด 3/ราดร่อง | U12: Fully | V12: 16 | W12: 14568 | X12: กษมา | Z12: 18.21 | AA12: อุปกรณ์ผู้รับเหมา | AC12: คู่ | AD12: 1.85 | AE12: เหนียว
A13: 1 | B13: กระทุ่ม 1 | C13: 11 | D13: 902 | E13: 617 | F13: 111 | G13: 902111 | H13: 45.72 | J13: 45.72 | K13: อ้อยตอ 1 | L13: อ้อยตอ | M13: KK-3 | N13: Fully | O13: 6 | P13: สระ 902302 | Q13: 590000 | R13: น้ำฝน | S13: เครื่องยนต์สูบน้ำ/โรงสูบน้ำ Solar Cell | T13: น้ำหยด 3/ราดร่อง | U13: Fully | V13: 16 | W13: 36576 | X13: กษมา | Z13: 46.4 | AA13: อุปกรณ์ผู้รับเหมา | AC13: เดี่ยว | AD13: 1.85 | AE13: เหนียว
A14: 1 | B14: กระทุ่ม 1 | C14: 12 | D14: 902 | E14: 606 | F14: 112 | G14: 902112 | H14: 8.58 | J14: 8.58 | K14: อ้อยน้ำราด | L14: อ้อยปลูก | M14: KK-3 | N14: Fully | O14: 6 | P14: สระ 902302 | Q14: 590000 | R14: น้ำฝน | S14: เครื่องยนต์สูบน้ำ/โรงสูบน้ำ Solar Cell | T14: น้ำหยด 3/ราดร่อง | U14: Fully | V14: 16 | W14: 6864 | X14: กษมา | Z14: 9.87 | AA14: อุปกรณ์ผู้รับเหมา | AC14: คู่ | AD14: 1.85 | AE14: เหนียว
A15: 1 | B15: กระทุ่ม 1 | C15: 13 | D15: 902 | E15: 605 | F15: 113 | G15: 902113 | H15: 13.96 | J15: 13.96 | K15: อ้อยน้ำราด | L15: อ้อยปลูก | M15: KK-3 | N15: Fully | O15: 6 | P15: สระ 902302 | Q15: 590000 | R15: น้ำฝน | S15: เครื่องยนต์สูบน้ำ/โรงสูบน้ำ Solar Cell | T15: น้ำหยด 3/ราดร่อง | U15: Fully | V15: 16 | W15: 11168 | X15: กษมา | Z15: 13.96 | AA15: อุปกรณ์ผู้รับเหมา | AC15: คู่ | AD15: 1.85 | AE15: เหนียว
A16: 1 | B16: กระทุ่ม 1 | C16: 14 | D16: 902 | E16: 604 | F16: 114 | G16: 902114 | H16: 11.75 | J16: 11.75 | K16: อ้อยน้ำราด | L16: อ้อยปลูก | M16: KK-3 | N16: Fully | O16: 6 | P16: สระ 902302 | Q16: 590000 | R16: น้ำฝน | S16: เครื่องยนต์สูบน้ำ/โรงสูบน้ำ Solar Cell | T16: น้ำหยด 3/ราดร่อง | U16: Fully | V16: 16 | W16: 9400 | X16: กษมา | Z16: 11.75 | AA16: อุปกรณ์ผู้รับเหมา | AC16: คู่ | AD16: 1.85 | AE16: เหนียว
A17: 1 | B17: กระทุ่ม 1 | C17: 15 | D17: 902 | E17: 601 | F17: 115 | G17: 902115 | H17: 25.3 | J17: 25.3 | K17: อ้อยน้ำราด | L17: อ้อยปลูก | M17: KK-3,MPT-618 | N17: Fully | O17: 6 | P17: สระ 902302 | Q17: 590000 | R17: น้ำฝน | S17: เครื่องยนต์สูบน้ำ/โรงสูบน้ำ Solar Cell | T17: น้ำหยด 3/ราดร่อง | U17: Fully | V17: 16 | W17: 20240 | X17: กษมา | Z17: 25.3 | AA17: อุปกรณ์ผู้รับเหมา | AC17: คู่ | AD17: 1.85 | AE17: เหนียว
A18: 1 | B18: กระทุ่ม 1 | C18: 16 | D18: 902 | E18: 718 | F18: 116 | G18: 902116 | H18: 11.98 | J18: 11.98 | K18: อ้อยน้ำราด | L18: อ้อยปลูก | M18: KK-3 | N18: Fully | O18: 6 | P18: สระ 902302 | Q18: 590000 | R18: น้ำฝน | S18: เครื่องยนต์สูบน้ำ/โรงสูบน้ำ Solar Cell | T18: น้ำหยด 3/ราดร่อง | U18: Fully | V18: 16 | W18: 9584 | X18: กษมา | Z18: 11.98 | AA18: อุปกรณ์ผู้รับเหมา | AC18: เดี่ยว | AD18: 1.65 | AE18: เหนียว
A19: 1 | B19: กระทุ่ม 1 | C19: 17 | D19: 902 | E19: 719 | F19: 117 | G19: 902117 | H19: 16.54 | J19: 16.54 | K19: อ้อยตุลาคม | L19: อ้อยปลูก | M19: KK-3 | N19: Fully | O19: 6 | P19: สระ 902302 | Q19: 590000 | R19: น้ำฝน | S19: เครื่องยนต์สูบน้ำ/โรงสูบน้ำ Solar Cell | T19: น้ำหยด 3/ราดร่อง | U19: Fully | V19: 16 | W19: 13232 | X19: กษมา | Z19: 16.54 | AA19: อุปกรณ์ผู้รับเหมา | AC19: เดี่ยว | AD19: 1.65 | AE19: เหนียว
A20: 1 | B20: กระทุ่ม 1 | C20: 18 | D20: 902 | E20: 720 | F20: 118 | G20: 902118 | H20: 10.24 | J20: 10.24 | K20: อ้อยตุลาคม | L20: อ้อยปลูก | M20: KK-3/PK-2 | N20: Fully | O20: 6 | P20: สระ 902302 | Q20: 590000 | R20: น้ำฝน | S20: เครื่องยนต์สูบน้ำ/โรงสูบน้ำ Solar Cell | T20: น้ำหยด 3/ราดร่อง | U20: Fully | V20: 16 | W20: 8192 | X20: กษมา | Z20: 10.24 | AA20: อุปกรณ์ผู้รับเหมา | AC20: เดี่ยว | AD20: 1.65 | AE20: เหนียว
A21: 1 | B21: กระทุ่ม 1 | C21: 19 | D21: 902 | E21: 721 | F21: 119 | G21: 902119 | H21: 5.37 | I21: 5.37 | K21: พักดิน | L21: พักดิน | M21: KK-3 | N21: Fully | O21: 6 | P21: สระ 902302 | Q21: 590000 | R21: น้ำฝน | S21: เครื่องยนต์สูบน้ำ/โรงสูบน้ำ Solar Cell | T21: น้ำหยด 3/ราดร่อง | U21: Fully | V21: 16 | W21: 0 | X21: กษมา | Z21: 5.37 | AA21: อุปกรณ์ผู้รับเหมา | AC21: คู่ | AD21: 1.85 | AE21: เหนียว
A22: 1 | B22: กระทุ่ม 1 | C22: 20 | D22: 902 | E22: 725 | F22: 120 | G22: 902120 | H22: 20.5 | J22: 20.5 | K22: อ้อยตอ 1 | L22: อ้อยตอ | M22: Csb08-108 | N22: Fully | O22: 6 | P22: สระ 902302 | Q22: 590000 | R22: น้ำฝน | S22: เครื่องยนต์สูบน้ำ/โรงสูบน้ำ Solar Cell | T22: น้ำหยด 3/ราดร่อง | U22: Fully | V22: 16 | W22: 16400 | X22: กษมา | Z22: 20.5 | AA22: อุปกรณ์ผู้รับเหมา | AC22: คู่ | AD22: 1.85 | AE22: เหนียว
A23: 1 | B23: กระทุ่ม 1 | C23: 21 | D23: 902 | E23: 726 | F23: 121 | G23: 902121 | H23: 13.85 | J23: 13.85 | K23: อ้อยน้ำราด | L23: อ้อยปลูก | M23: ทองภูมิ 6 | N23: Fully | O23: 6 | P23: สระ 902302 | Q23: 590000 | R23: น้ำฝน | S23: เครื่องยนต์สูบน้ำ/โรงสูบน้ำ Solar Cell | T23: น้ำหยด 3/ราดร่อง | U23: Fully | V23: 16 | W23: 11080 | X23: กษมา | Z23: 13.85 | AA23: อุปกรณ์ผู้รับเหมา | AC23: คู่ | AD23: 1.85 | AE23: เหนียว
A24: 1 | B24: กระทุ่ม 1 | C24: 22 | D24: 902 | E24: 740 | F24: 122 | G24: 902122 | H24: 9.35 | J24: 9.35 | K24: อ้อยน้ำราด | L24: อ้อยปลูก | M24: kk-3 | N24: Fully | O24: 6 | P24: สระ 902302 | Q24: 590000 | R24: น้ำฝน | S24: เครื่องยนต์สูบน้ำ/โรงสูบน้ำ Solar Cell | T24: น้ำหยด 3/ราดร่อง | U24: Fully | V24: 16 | W24: 7480 | X24: กษมา | Z24: 9.35 | AA24: อุปกรณ์ผู้รับเหมา | AC24: คู่ | AD24: 1.85 | AE24: เหนียว
A25: 1 | B25: กระทุ่ม 1 | C25: 23 | D25: 902 | E25: 714 | F25: 123 | G25: 902123 | H25: 12.37 | J25: 12.37 | K25: อ้อยตอ 1 | L25: อ้อยตอ | M25: MPT14-618,KK3 | N25: Fully | O25: 6 | P25: สระ 902303 (โซล่า) | Q25: 103000 | R25: น้ำฝน | S25: โรงสูบน้ำ Solar Cell | T25: น้ำหยดบนดิน Fix | U25: Fully | V25: 9 | W25: 5566.5 | X25: กษมา | Z25: 12.37 | AA25: อุปกรณ์ผู้รับเหมา | AC25: เดี่ยว | AD25: 1.85 | AE25: เหนียว
A26: 1 | B26: กระทุ่ม 1 | C26: 24 | D26: 902 | E26: 715 | F26: 124 | G26: 902124 | H26: 59.33 | J26: 59.33 | K26: อ้อยน้ำราด | L26: อ้อยปลูก | M26: KK-3 | N26: Fully | O26: 6 | P26: สระ 902303 (โซล่า) | Q26: 103000 | R26: น้ำฝน | S26: โรงสูบน้ำ Solar Cell | T26: น้ำหยดบนดิน Fix | U26: Fully | V26: 9 | W26: 26698.5 | X26: กษมา | Z26: 59.33 | AA26: อุปกรณ์ผู้รับเหมา | AC26: คู่ | AD26: 1.85 | AE26: เหนียว
A27: 1 | B27: กระทุ่ม 1 | C27: 25 | D27: 902 | E27: 742 | F27: 125 | G27: 902125 | H27: 28.68 | J27: 28.68 | K27: อ้อยน้ำราด | L27: อ้อยปลูก | M27: PK-3 | N27: Fully | O27: 6 | P27: สระ 902302 | Q27: 590000 | R27: น้ำฝน | S27: เครื่องยนต์สุบน้ำ | T27: น้ำหยดบนดิน Move | U27: sup | V27: 3 | W27: 4302 | X27: กษมา | Z27: 31.85 | AA27: อุปกรณ์ผู้รับเหมา | AC27: คู่ | AD27: 1.85 | AE27: เหนียว
A28: 1 | B28: กระทุ่ม 1 | C28: 26 | D28: 902 | E28: 743 | F28: 126 | G28: 902126 | H28: 39.76 | J28: 39.76 | K28: อ้อยน้ำราด | L28: อ้อยปลูก | M28: MPT-442 | N28: Fully | O28: 6 | P28: สระ 902304 (ติดตั้งโซล่า) | Q28: 157000 | R28: น้ำฝน | S28: เครื่องยนต์สูบน้ำ/Solar Mobile | T28: น้ำหยดบนดิน Fix | U28: Fully | V28: 8 | W28: 15904 | X28: กษมา | Z28: 39.76 | AA28: อุปกรณ์ผู้รับเหมา | AC28: คู่ | AD28: 1.85 | AE28: เหนียว
A29: 1 | B29: กระทุ่ม 1 | C29: 27 | D29: 902 | E29: 743/1 | F29: 127 | G29: 902127 | H29: 55.36 | J29: 55.36 | K29: อ้อยน้ำราด | L29: อ้อยปลูก | M29: KK-3 | N29: Fully | O29: 6 | P29: สระ 902304 (ติดตั้งโซล่า) | Q29: 157000 | R29: น้ำฝน | S29: เครื่องยนต์สูบน้ำ/Solar Mobile | T29: น้ำหยดบนดิน Fix | U29: Fully | V29: 8 | W29: 22144 | X29: กษมา | Z29: 57.15 | AA29: อุปกรณ์ผู้รับเหมา | AC29: คู่ | AD29: 1.85 | AE29: เหนียว
A30: 1 | B30: กระทุ่ม 1 | C30: 28 | D30: 902 | E30: 744 | F30: 128 | G30: 902128 | H30: 141.89 | J30: 141.89 | K30: อ้อยตอ 1 | L30: อ้อยตอ | M30: MPT14-618,ทองภูมิ6 | N30: Fully | O30: 6 | P30: สระ 902304 (ติดตั้งโซล่า) | Q30: 157000 | R30: น้ำฝน | S30: เครื่องยนต์สูบน้ำ/Solar Mobile | T30: น้ำหยดบนดิน Fix | U30: Fully | V30: 8 | W30: 56756 | X30: กษมา | Z30: 146.13 | AA30: อุปกรณ์ผู้รับเหมา | AC30: คู่ | AD30: 1.85 | AE30: เหนียว
A31: 1 | B31: กระทุ่ม 1 | C31: 29 | D31: 902 | E31: 745 | F31: 129 | G31: 902129 | H31: 19.85 | J31: 19.85 | K31: อ้อยน้ำราด | L31: อ้อยปลูก | M31: KK-3,MPT-358 | N31: Fully | O31: 6 | P31: สระ 902304 (ติดตั้งโซล่า) | Q31: 157000 | R31: น้ำฝน | S31: เครื่องยนต์สูบน้ำ/Solar Mobile | T31: น้ำหยดบนดิน Fix | U31: Fully | V31: 8 | W31: 7940 | X31: กษมา | Z31: 22.39 | AA31: อุปกรณ์ผู้รับเหมา | AC31: คู่ | AD31: 1.85 | AE31: เหนียว
A32: 1 | B32: กระทุ่ม 1 | C32: 30 | D32: 902 | E32: 746 | F32: 130 | G32: 902130 | H32: 17.31 | J32: 17.31 | K32: อ้อยน้ำราด | L32: อ้อยปลูก | M32: เอราวัณ | N32: Fully | O32: 6 | P32: สระ 902302 | Q32: 590000 | R32: น้ำฝน | S32: เครื่องยนต์สุบน้ำ | T32: น้ำหยดบนดิน Move | U32: sup | V32: 3 | W32: 2596.5 | X32: กษมา | Z32: 19.22 | AA32: อุปกรณ์ผู้รับเหมา | AC32: คู่ | AD32: 1.85 | AE32: เหนียว
A33: 1 | B33: กระทุ่ม 1 | C33: 31 | D33: 902 | E33: 731 | F33: 131 | G33: 902131 | H33: 11.3 | J33: 11.3 | K33: อ้อยตอ 1 | L33: อ้อยตอ | M33: ทองภูมิ6 | N33: Fully | O33: 6 | P33: สระ 902304 (ติดตั้งโซล่า) | Q33: 157000 | R33: น้ำฝน | S33: เครื่องยนต์สูบน้ำ/Solar Mobile | T33: น้ำหยดบนดิน Fix | U33: Fully | V33: 8 | W33: 4520 | X33: กษมา | Z33: 11.3 | AA33: อุปกรณ์ผู้รับเหมา | AC33: คู่ | AD33: 1.85 | AE33: เหนียว
A34: 1 | B34: กระทุ่ม 1 | C34: 32 | D34: 902 | E34: 732 | F34: 132 | G34: 902132 | H34: 23.21 | J34: 23.21 | K34: อ้อยตอ 1 | L34: อ้อยตอ | M34: ทองภูมิ6 | N34: Fully | O34: 6 | P34: สระ 902304 (ติดตั้งโซล่า) | Q34: 157000 | R34: น้ำฝน | S34: เครื่องยนต์สูบน้ำ/Solar Mobile | T34: น้ำหยดบนดิน Fix | U34: Fully | V34: 8 | W34: 9284 | X34: กษมา | Z34: 23.21 | AA34: อุปกรณ์ผู้รับเหมา | AC34: คู่ | AD34: 1.85 | AE34: เหนียว
A35: 1 | B35: กระทุ่ม 1 | C35: 33 | D35: 902 | E35: 733 | F35: 133 | G35: 902133 | H35: 24.2 | J35: 24.2 | K35: อ้อยตอ 1 | L35: อ้อยตอ | M35: MPT12-74 | N35: Fully | O35: 6 | P35: สระ 902304 (ติดตั้งโซล่า) | Q35: 157000 | R35: น้ำฝน | S35: เครื่องยนต์สูบน้ำ/Solar Mobile | T35: น้ำหยดบนดิน Fix | U35: Fully | V35: 8 | W35: 9680 | X35: กษมา | Z35: 24.2 | AA35: อุปกรณ์ผู้รับเหมา | AC35: คู่ | AD35: 1.85 | AE35: เหนียว
A36: 1 | B36: กระทุ่ม 1 | C36: 34 | D36: 902 | E36: 734 | F36: 134 | G36: 902134 | H36: 24.81 | J36: 24.81 | K36: อ้อยตอ 1 | L36: อ้อยตอ | M36: MPT12-74 | N36: Fully | O36: 6 | P36: สระ 902304 (ติดตั้งโซล่า) | Q36: 157000 | R36: น้ำฝน | S36: เครื่องยนต์สูบน้ำ/Solar Mobile | T36: น้ำหยดบนดิน Fix | U36: Fully | V36: 8 | W36: 9924 | X36: กษมา | Z36: 24.81 | AA36: อุปกรณ์ผู้รับเหมา | AC36: คู่ | AD36: 1.85 | AE36: เหนียว
A37: 1 | B37: กระทุ่ม 1 | C37: 35 | D37: 902 | E37: 735 | F37: 135 | G37: 902135 | H37: 25.22 | J37: 25.22 | K37: อ้อยน้ำราด | L37: อ้อยปลูก | M37: KK-3,MPT-12-74 | N37: Fully | O37: 6 | P37: สระ 902304 (ติดตั้งโซล่า) | Q37: 157000 | R37: น้ำฝน | S37: เครื่องยนต์สูบน้ำ/Solar Mobile | T37: น้ำหยดบนดิน Fix | U37: Fully | V37: 8 | W37: 10088 | X37: กษมา | Z37: 27.35 | AA37: อุปกรณ์ผู้รับเหมา | AC37: คู่ | AD37: 1.85 | AE37: เหนียว
A38: 1 | B38: กระทุ่ม 1 | C38: 36 | D38: 902 | E38: 711 | F38: 136 | G38: 902136 | H38: 68.26 | J38: 68.26 | K38: อ้อยตอ 1 | L38: อ้อยตอ | M38: MPT-12-1782,KK-3 | N38: Fully | O38: 6 | P38: สระ 902303 (โซล่า) | Q38: 103000 | R38: น้ำฝน | S38: โรงสูบน้ำ Solar Cell | T38: น้ำหยดบนดิน Fix | U38: Fully | V38: 9 | W38: 30717 | X38: กษมา | Z38: 68.26 | AA38: อุปกรณ์ผู้รับเหมา | AC38: คู่ | AD38: 1.85 | AE38: เหนียว
A39: 1 | B39: กระทุ่ม 1 | C39: 37 | D39: 902 | E39: 640 | F39: 137 | G39: 902137 | H39: 20.45 | J39: 20.45 | K39: อ้อยน้ำราด | L39: อ้อยปลูก | M39: KK-3 | N39: sup | O39: 3 | P39: สระ 902304 | Q39: 157000 | R39: น้ำฝน | S39: เครื่องยนต์สุบน้ำ | T39: น้ำหยดบนดิน Move | U39: sup | V39: 5 | W39: 5112.5 | X39: กษมา | Z39: 20.45 | AA39: อุปกรณ์ผู้รับเหมา | AC39: คู่ | AD39: 1.85 | AE39: เหนียว
A40: 1 | B40: กระทุ่ม 1 | C40: 38 | D40: 902 | E40: 701 | F40: 138 | G40: 902138 | H40: 33.7 | I40: 33.7 | K40: พักดิน | L40: พักดิน | M40: KK-3 | N40: Fully | O40: 6 | P40: สระ 902305 | Q40: 26950 | R40: น้ำฝน | S40: เครื่องยนต์สุบน้ำ | T40: น้ำหยดบนดิน Move | U40: sup | V40: 3 | W40: 0 | X40: กษมา | Z40: 33.7 | AA40: อุปกรณ์ผู้รับเหมา | AC40: เดี่ยว | AD40: 1.65 | AE40: เหนียว
A41: 1 | B41: กระทุ่ม 1 | C41: 39 | D41: 902 | E41: 702 | F41: 139 | G41: 902139 | H41: 36.86 | I41: 36.86 | K41: พักดิน | L41: พักดิน | M41: KK-3 | N41: Fully | O41: 6 | P41: สระ 902305 | Q41: 26950 | R41: น้ำฝน | S41: เครื่องยนต์สุบน้ำ | T41: น้ำหยดบนดิน Move | U41: sup | V41: 3 | W41: 0 | X41: กษมา | Z41: 36.86 | AA41: อุปกรณ์ผู้รับเหมา | AC41: เดี่ยว | AD41: 1.65 | AE41: เหนียว
...

Sheet วิเคราะห์ดินปี59-63
A1: ผลวเคราะห์ดินทั้งหมดของไร่ด่านช้าง ( ปี 59-61 ) | U1: สูตรปุ๋ยแนะนำตามค่าวิเคราะห์ดินอ้อยปลูก
A2: ลำดับที่ | B2: ปี | C2: ชื่อไร่ | D2: หมายเลขแปลง | F2: ผลการวิเคราะห์ | R2: อ้อยปลูก (กก./ไร่) | U2: สูตรรองพื้น | Y2: อัตรา (กก/ไร่) | Z2: สูตรแต่งหน้า | AD2: อัตรา (กก/ไร่) | AE2: ธาตุอาหารที่ได้ (กก/ไร่) | AH2: ความต้องการธาตุอาหารอ้อยตอ ( กก./ไร่) | AK2: สูตร/อัตรา รองพื้น ( อ้อยตอ ) | AN2: รองพื้น | AO2: อัตรา ( กก./ไร่) | AP2: สูตร/อัตรา, แต่งหน้าอ้อยตอ | AS2: อัตรา ( กก./ไร่ ) | AT2: ปริมาณธาตุอาหารอ้อบตอ ( กก./ไร่ )
F3: pH | G3: pH-Level | H3: EC saturated (dS/m) | I3: OM (%) | J3: OM-Level | K3: P (ppm) | L3: P-Level | M3: K (ppm) | N3: K-Level | O3: Ca (ppm) | P3: Mg (ppm) | Q3: Na (ppm) | R3: N | S3: P | T3: K | U3: N | V3: P | W3: K | Z3: N | AA3: P | AB3: K | AE3: N | AF3: P | AG3: K | AH3: N | AI3: P | AJ3: K | AK3: N | AL3: P | AM3: K | AP3: N | AQ3: P | AR3: K | AT3: N | AU3: P | AV3: K
A4: 3 | B4: 59 | C4: ไร่หนองขอน | D4: 874 | E4: =VLOOKUP(D4,รายแปลง!E:G,3,FALSE) -> 903118 | F4: 8.18 | G4: ด่างอ่อน | H4: 3.63256 | I4: 1.4734137 | J4: ต่ำ | K4: 22.436111 | L4: ปานกลาง | M4: 273.6147 | N4: สูงมาก | O4: 5094.9553 | P4: 167.84176 | Q4: 265.67712 | R4: 15 | S4: 9 | T4: 10 | U4: 16 | V4: 16 | W4: 8 | X4: 16-16-8 | Y4: 50 | Z4: 21 | AA4: 7 | AB4: 18 | AC4: 21-7-18 | AD4: 50 | AE4: 18.5 | AF4: 11.5 | AG4: 13
A5: 4 | B5: 59 | C5: ไร่หนองขอน | D5: 875 | E5: =VLOOKUP(D5,รายแปลง!E:G,3,FALSE) -> 903119 | F5: 7.95 | G5: ด่างอ่อน | H5: 5.34364 | I5: 2.5114673 | J5: สูง | K5: 68.465562 | L5: สูง | M5: 360.76753 | N5: สูงมาก | O5: 4751.8287 | P5: 167.05023 | Q5: 535.00748 | R5: 12 | S5: 6 | T5: 10 | U5: 16 | V5: 8 | W5: 8 | X5: 16-8-8 | Y5: 50 | Z5: 21 | AA5: 7 | AB5: 18 | AC5: 21-7-18 | AD5: 50 | AE5: 18.5 | AF5: 7.5 | AG5: 13
A6: 5 | B6: 59 | C6: ไร่หนองขอน | D6: 877 | E6: =VLOOKUP(D6,รายแปลง!E:G,3,FALSE) -> 903123 | F6: 8.545 | G6: ด่างแก่ | H6: 7.91908 | I6: 2.1810164 | J6: ปานกลาง | K6: 34.053236 | L6: ปานกลาง | M6: 416.61393 | N6: สูงมาก | O6: 3506.9292 | P6: 161.6241 | Q6: 866.99507 | R6: 12 | S6: 6 | T6: 10 | U6: 16 | V6: 8 | W6: 8 | X6: 16-8-8 | Y6: 50 | Z6: 21 | AA6: 7 | AB6: 18 | AC6: 21-7-18 | AD6: 50 | AE6: 18.5 | AF6: 7.5 | AG6: 13
A7: 8 | B7: 59 | C7: ไร่หนองขอน | D7: 2003 | E7: =VLOOKUP(D7,รายแปลง!E:G,3,FALSE) -> 901140 | F7: 8.3 | G7: ด่างอ่อน | H7: 4.21468 | I7: 1.1681576 | J7: ต่ำ | K7: 172.64362 | L7: สูง | M7: 471.24347 | N7: สูงมาก | O7: 3864.8697 | P7: 157.36324 | Q7: 87.815776 | R7: 15 | S7: 6 | T7: 10 | U7: 16 | V7: 8 | W7: 8 | X7: 16-8-8 | Y7: 50 | Z7: 21 | AA7: 7 | AB7: 18 | AC7: 21-7-18 | AD7: 50 | AE7: 18.5 | AF7: 7.5 | AG7: 13
A8: 9 | B8: 59 | C8: ไร่หนองขอน | D8: 2004 | E8: =VLOOKUP(D8,รายแปลง!E:G,3,FALSE) -> 901139 | F8: 8.195 | G8: ด่างอ่อน | H8: 4.74976 | I8: 1.2378433 | J8: ต่ำ | K8: 176.09857 | L8: สูง | M8: 457.42047 | N8: สูงมาก | O8: 3796.0841 | P8: 171.99397 | Q8: 63.872538 | R8: 15 | S8: 6 | T8: 10 | U8: 16 | V8: 8 | W8: 8 | X8: 16-8-8 | Y8: 50 | Z8: 21 | AA8: 7 | AB8: 18 | AC8: 21-7-18 | AD8: 50 | AE8: 18.5 | AF8: 7.5 | AG8: 13
A9: 10 | B9: 59 | C9: ไร่หนองขอน | D9: 2006 | E9: =VLOOKUP(D9,รายแปลง!E:G,3,FALSE) -> 901136 | F9: 8.43 | G9: ด่างแก่ | H9: 4.37344 | I9: 0.83368771 | J9: ต่ำมาก | K9: 186.93631 | L9: สูง | M9: 240.74227 | N9: สูงมาก | O9: 2949.261 | P9: 200.4374 | Q9: 294.63865 | R9: 18 | S9: 6 | T9: 10 | U9: 16 | V9: 16 | W9: 8 | X9: 16-16-8 | Y9: 50 | Z9: 21 | AA9: 7 | AB9: 18 | AC9: 21-7-18 | AD9: 50 | AE9: 18.5 | AF9: 11.5 | AG9: 13
A10: 11 | B10: 59 | C10: ไร่หนองขาม | D10: 206 | E10: =VLOOKUP(D10,รายแปลง!E:G,3,FALSE) -> 911101 | F10: 6.675 | G10: ปานกลาง | H10: 2.169616 | I10: 0.40197366 | J10: ต่ำมาก | K10: 20.026872 | L10: ปานกลาง | M10: 114.05966 | N10: สูง | O10: 256.70574 | P10: 75.994081 | Q10: 33.134139 | R10: 18 | S10: 9 | T10: 10 | U10: 16 | V10: 16 | W10: 8 | X10: 16-16-8 | Y10: 50 | Z10: 21 | AA10: 7 | AB10: 18 | AC10: 21-7-18 | AD10: 50 | AE10: 18.5 | AF10: 11.5 | AG10: 13
A11: 17 | B11: 59 | C11: ไร่หนองขาม | D11: 230 | E11: =VLOOKUP(D11,รายแปลง!E:G,3,FALSE) -> 911113 | F11: 7.92 | G11: ด่างอ่อน | H11: 4.69684 | I11: 1.0322084 | J11: ต่ำ | K11: 54.5043 | L11: สูง | M11: 291.87989 | N11: สูงมาก | O11: 3132.6882 | P11: 392.6995 | Q11: 218.83461 | R11: 15 | S11: 6 | T11: 10 | U11: 16 | V11: 8 | W11: 8 | X11: 16-8-8 | Y11: 50 | Z11: 21 | AA11: 7 | AB11: 18 | AC11: 21-7-18 | AD11: 50 | AE11: 18.5 | AF11: 7.5 | AG11: 13
A12: 18 | B12: 59 | C12: ไร่หนองขาม | D12: 233 | E12: =VLOOKUP(D12,รายแปลง!E:G,3,FALSE) -> 911118 | F12: 6.335 | G12: ปานกลาง | H12: 4.58512 | I12: 1.1743419 | J12: ต่ำ | K12: 16.557215 | L12: ต่ำ | M12: 356.30754 | N12: สูงมาก | O12: 1790.271 | P12: 163.6361 | Q12: 412.81591 | R12: 15 | S12: 9 | T12: 10 | U12: 16 | V12: 16 | W12: 8 | X12: 16-16-8 | Y12: 50 | Z12: 21 | AA12: 7 | AB12: 18 | AC12: 21-7-18 | AD12: 50 | AE12: 18.5 | AF12: 11.5 | AG12: 13
A13: 19 | B13: 59 | C13: ไร่หนองขาม | D13: 234 | E13: =VLOOKUP(D13,รายแปลง!E:G,3,FALSE) -> 911116 | F13: 8.04 | G13: ด่างอ่อน | H13: 4.01476 | I13: 1.0277491 | J13: ต่ำ | K13: 32.930435 | L13: ปานกลาง | M13: 327.63425 | N13: สูงมาก | O13: 3997.0917 | P13: 144.23807 | Q13: 83.525312 | R13: 15 | S13: 6 | T13: 10 | U13: 16 | V13: 8 | W13: 8 | X13: 16-8-8 | Y13: 50 | Z13: 21 | AA13: 7 | AB13: 18 | AC13: 21-7-18 | AD13: 50 | AE13: 18.5 | AF13: 7.5 | AG13: 13
A14: 20 | B14: 59 | C14: ไร่หนองขาม | D14: 235 | E14: =VLOOKUP(D14,รายแปลง!E:G,3,FALSE) -> 911117 | F14: 7.685 | G14: ด่างอ่อน | H14: 5.48476 | I14: 1.327821 | J14: ต่ำ | K14: 36.800157 | L14: ปานกลาง | M14: 313.41397 | N14: สูงมาก | O14: 2592.803 | P14: 195.03624 | Q14: 90.525309 | R14: 15 | S14: 6 | T14: 10 | U14: 16 | V14: 8 | W14: 8 | X14: 16-8-8 | Y14: 50 | Z14: 21 | AA14: 7 | AB14: 18 | AC14: 21-7-18 | AD14: 50 | AE14: 18.5 | AF14: 7.5 | AG14: 13
A15: 21 | B15: 59 | C15: ไร่หนองขาม | D15: 239 | E15: =VLOOKUP(D15,รายแปลง!E:G,3,FALSE) -> 911119 | F15: 7.33 | G15: ด่างอ่อน | H15: 2.7682 | I15: 1.4997607 | J15: ต่ำ | K15: 19.178002 | L15: ต่ำ | M15: 242.80027 | N15: สูงมาก | O15: 2246.6432 | P15: 399.69616 | Q15: 42.254397 | R15: 15 | S15: 9 | T15: 10 | U15: 16 | V15: 16 | W15: 8 | X15: 16-16-8 | Y15: 50 | Z15: 21 | AA15: 7 | AB15: 18 | AC15: 21-7-18 | AD15: 50 | AE15: 18.5 | AF15: 11.5 | AG15: 13
... A66: 132 | B66: 59 | C66: ไร่เขาแหลม | D66: 1229 | E66: =VLOOKUP(D66,รายแปลง!E:G,3,FALSE) -> 907124 | F66: 7.75 | G66: ด่างอ่อน | H66: 4.7086 | I66: 2.2921866 | J66: ปานกลาง | K66: 32.024985 | L66: ปานกลาง | M66: 226.62367 | N66: สูงมาก | O66: 6631.7307 | P66: 75.854397 | Q66: 1792.8017 | R66: 12 | S66: 6 | T66: 10 | U66: 16 | V66: 8 | W66: 8 | X66: 16-8-8 | Y66: 50 | Z66: 21 | AA66: 7 | AB66: 18 | AC66: 21-7-18 | AD66: 50 | AE66: 18.5 | AF66: 7.5 | AG66: 13
A67: 139 | B67: 59 | C67: ไร่หนองกระทุ่ม1 | D67: 617 | E67: =VLOOKUP(D67,รายแปลง!E:G,3,FALSE) -> 902111 | F67: 7.57 | G67: ด่างอ่อน | H67: 0.46 | I67: 0.535 | J67: ต่ำมาก | K67: 21.33 | L67: ปานกลาง | M67: 49.89 | N67: ต่ำ | Q67: 211.22 | R67: 18 | S67: 9 | T67: 15 | U67: 16 | V67: 16 | W67: 8 | X67: 16-16-8 | Y67: 50 | Z67: 20 | AA67: 8 | AB67: 20 | AC67: 20-8-20 | AD67: 50 | AE67: 18 | AF67: 12 | AG67: 14
A68: 140 | B68: 59 | C68: ไร่หนองกระทุ่ม1 | D68: 620 | E68: =VLOOKUP(D68,รายแปลง!E:G,3,FALSE) -> 902106 | F68: 7.21 | G68: ปานกลาง | H68: 0.31 | I68: 0.799 | J68: ต่ำมาก | K68: 69.63 | L68: สูง | M68: 91.23 | N68: สูง | R68: 18 | S68: 6 | T68: 10 | U68: 16 | V68: 16 | W68: 8 | X68: 16-16-8 | Y68: 50 | Z68: 21 | AA68: 7 | AB68: 18 | AC68: 21-7-18 | AD68: 50 | AE68: 18.5 | AF68: 11.5 | AG68: 13
A69: 142 | B69: 59 | C69: ไร่หนองกระทุ่ม1 | D69: 634 | E69: =VLOOKUP(D69,รายแปลง!E:G,3,FALSE) -> 902101 | F69: 7.97 | G69: ด่างอ่อน | H69: 0.14 | I69: 0.778 | J69: ต่ำมาก | K69: 103.36 | L69: สูง | M69: 116.3 | N69: สูง | Q69: 267.95 | R69: 18 | S69: 6 | T69: 10 | U69: 16 | V69: 16 | W69: 8 | X69: 16-16-8 | Y69: 50 | Z69: 21 | AA69: 7 | AB69: 18 | AC69: 21-7-18 | AD69: 50 | AE69: 18.5 | AF69: 11.5 | AG69: 13
A70: 148 | B70: 59 | C70: ไร่หนองกระทุ่ม1 | D70: 711 | E70: =VLOOKUP(D70,รายแปลง!E:G,3,FALSE) -> 902136 | F70: 7.83 | G70: ด่างอ่อน | H70: 0.19 | I70: 0.634 | J70: ต่ำมาก | K70: 108.32 | L70: สูง | M70: 39.25 | N70: ต่ำ | Q70: 133.63 | R70: 18 | S70: 6 | T70: 15 | U70: 16 | V70: 8 | W70: 8 | X70: 16-8-8 | Y70: 50 | Z70: 20 | AA70: 8 | AB70: 20 | AC70: 20-8-20 | AD70: 50 | AE70: 18 | AF70: 8 | AG70: 14
A71: 149 | B71: 59 | C71: ไร่หนองกระทุ่ม1 | D71: 714 | E71: =VLOOKUP(D71,รายแปลง!E:G,3,FALSE) -> 902123 | F71: 7.81 | G71: ด่างอ่อน | H71: 0.39 | I71: 1.616 | J71: ปานกลาง | K71: 444.22 | L71: สูง | M71: 127.23 | N71: สูงมาก | Q71: 348.48 | R71: 15 | S71: 6 | T71: 10 | U71: 16 | V71: 8 | W71: 8 | X71: 16-8-8 | Y71: 50 | Z71: 21 | AA71: 7 | AB71: 18 | AC71: 21-7-18 | AD71: 50 | AE71: 18.5 | AF71: 7.5 | AG71: 13
A72: 150 | B72: 59 | C72: ไร่หนองกระทุ่ม1 | D72: 715 | E72: =VLOOKUP(D72,รายแปลง!E:G,3,FALSE) -> 902124 | F72: 7.07 | G72: ปานกลาง | H72: 0.26 | I72: 1.232 | J72: ต่ำ | K72: 336.7 | L72: สูง | M72: 76.41 | N72: ปานกลาง | Q72: 225.69 | R72: 15 | S72: 6 | T72: 12 | U72: 16 | V72: 16 | W72: 8 | X72: 16-16-8 | Y72: 50 | Z72: 15 | AA72: 7 | AB72: 18 | AC72: 15-7-18 | AD72: 50 | AE72: 15.5 | AF72: 11.5 | AG72: 13
A73: 151 | B73: 59 | C73: ไร่หนองกระทุ่ม1 | D73: 718 | E73: =VLOOKUP(D73,รายแปลง!E:G,3,FALSE) -> 902116 | F73: 8.21 | G73: ด่างอ่อน | H73: 0.33 | I73: 0.684 | J73: ต่ำมาก | K73: 70.32 | L73: สูง | M73: 51.49 | N73: ต่ำ | Q73: 450.95 | R73: 18 | S73: 6 | T73: 15 | U73: 16 | V73: 8 | W73: 8 | X73: 16-8-8 | Y73: 50 | Z73: 20 | AA73: 8 | AB73: 20 | AC73: 20-8-20 | AD73: 50 | AE73: 18 | AF73: 8 | AG73: 14
A74: 152 | B74: 59 | C74: ไร่หนองกระทุ่ม1 | D74: 719 | E74: =VLOOKUP(D74,รายแปลง!E:G,3,FALSE) -> 902117 | F74: 6.84 | G74: ปานกลาง | H74: 0.071 | I74: 0.696 | J74: ต่ำมาก | K74: 75.86 | L74: สูง | M74: 64.11 | N74: ปานกลาง | Q74: 133.37 | R74: 18 | S74: 6 | T74: 12 | U74: 16 | V74: 16 | W74: 8 | X74: 16-16-8 | Y74: 50 | Z74: 21 | AA74: 7 | AB74: 18 | AC74: 21-7-18 | AD74: 50 | AE74: 18.5 | AF74: 11.5 | AG74: 13
A75: 153 | B75: 59 | C75: ไร่หนองกระทุ่ม1 | D75: 720 | E75: =VLOOKUP(D75,รายแปลง!E:G,3,FALSE) -> 902118 | F75: 7.3 | G75: ปานกลาง | H75: 0.18 | I75: 1.101 | J75: ต่ำ | K75: 180.44 | L75: สูง | M75: 126.69 | N75: สูงมาก | Q75: 253.21 | R75: 15 | S75: 6 | T75: 10 | U75: 16 | V75: 8 | W75: 8 | X75: 16-8-8 | Y75: 50 | Z75: 21 | AA75: 7 | AB75: 18 | AC75: 21-7-18 | AD75: 50 | AE75: 18.5 | AF75: 7.5 | AG75: 13
A76: 154 | B76: 59 | C76: ไร่หนองกระทุ่ม1 | D76: 732 | E76: =VLOOKUP(D76,รายแปลง!E:G,3,FALSE) -> 902132 | F76: 7.03 | G76: ปานกลาง | H76: 0.23 | I76: 0.585 | J76: ต่ำมาก | K76: 30.11 | L76: ปานกลาง | M76: 64.5 | N76: ปานกลาง | Q76: 187.52 | R76: 18 | S76: 6 | T76: 12 | U76: 16 | V76: 16 | W76: 8 | X76: 16-16-8 | Y76: 50 | Z76: 21 | AA76: 7 | AB76: 18 | AC76: 21-7-18 | AD76: 50 | AE76: 18.5 | AF76: 11.5 | AG76: 13
A77: 155 | B77: 59 | C77: ไร่หนองกระทุ่ม1 | D77: 733 | E77: =VLOOKUP(D77,รายแปลง!E:G,3,FALSE) -> 902133 | F77: 8 | G77: ด่างอ่อน | H77: 0.25 | I77: 0.446 | J77: ต่ำมาก | K77: 35.69 | L77: ปานกลาง | M77: 241.46 | N77: สูงมาก | Q77: 471.99 | R77: 18 | S77: 6 | T77: 10 | U77: 16 | V77: 16 | W77: 8 | X77: 16-16-8 | Y77: 50 | Z77: 21 | AA77: 7 | AB77: 18 | AC77: 21-7-18 | AD77: 50 | AE77: 18.5 | AF77: 11.5 | AG77: 13
A78: 156 | B78: 59 | C78: ไร่หนองกระทุ่ม1 | D78: 734 | E78: =VLOOKUP(D78,รายแปลง!E:G,3,FALSE) -> 902134 | F78: 8.16 | G78: ด่างอ่อน | H78: 0.11 | I78: 0.995 | J78: ต่ำมาก | K78: 90.68 | L78: สูง | M78: 76.77 | N78: ปานกลาง | Q78: 93.85 | R78: 18 | S78: 6 | T78: 12 | U78: 16 | V78: 16 | W78: 8 | X78: 16-16-8 | Y78: 50 | Z78: 21 | AA78: 7 | AB78: 18 | AC78: 21-7-18 | AD78: 50 | AE78: 18.5 | AF78: 11.5 | AG78: 13
A79: 157 | B79: 59 | C79: ไร่หนองกระทุ่ม1 | D79: 735 | E79: =VLOOKUP(D79,รายแปลง!E:G,3,FALSE) -> 902135 | F79: 8.73 | G79: ด่างแก่ | H79: 0.25 | I79: 0.782 | J79: ต่ำมาก | K79: 174.46 | L79: สูง | M79: 176.96 | N79: สูงมาก | Q79: 601.25 | R79: 18 | S79: 6 | T79: 10 | U79: 16 | V79: 16 | W79: 8 | X79: 16-16-8 | Y79: 50 | Z79: 21 | AA79: 7 | AB79: 18 | AC79: 21-7-18 | AD79: 50 | AE79: 18.5 | AF79: 11.5 | AG79: 13
A80: 158 | B80: 59 | C80: ไร่หนองกระทุ่ม2 | D80: 723 | E80: =VLOOKUP(D80,รายแปลง!E:G,3,FALSE) -> 906148 | F80: 8.03 | G80: ด่างอ่อน | H80: 0.14 | I80: 0.773 | J80: ต่ำมาก | K80: 43.13 | L80: สูง | M80: 46.55 | N80: ต่ำ | Q80: 123.39 | R80: 18 | S80: 6 | T80: 15 | U80: 16 | V80: 8 | W80: 8 | X80: 16-8-8 | Y80: 50 | Z80: 20 | AA80: 8 | AB80: 20 | AC80: 20-8-20 | AD80: 50 | AE80: 18 | AF80: 8 | AG80: 14
... A90: 172 | B90: 59 | C90: ไร่หนองกระทุ่ม2 | D90: 919 | E90: =VLOOKUP(D90,รายแปลง!E:G,3,FALSE) -> 906111 | F90: 8.28 | G90: ด่างอ่อน | H90: 0.12 | I90: 1.157 | J90: ต่ำ | K90: 64.53 | L90: สูง | M90: 226.92 | N90: สูงมาก | Q90: 95.4 | R90: 15 | S90: 6 | T90: 10 | U90: 16 | V90: 8 | W90: 8 | X90: 16-8-8 | Y90: 50 | Z90: 21 | AA90: 7 | AB90: 18 | AC90: 21-7-18 | AD90: 50 | AE90: 18.5 | AF90: 7.5 | AG90: 13
A91: 181 | B91: 59 | C91: ไร่หนองกระทุ่ม2 | D91: 938 | E91: =VLOOKUP(D91,รายแปลง!E:G,3,FALSE) -> 906125 | F91: 6.7 | G91: ปานกลาง | H91: 4.59688 | I91: 1.5888952 | J91: ปานกลาง | K91: 291.29463 | L91: สูง | M91: 243.78349 | N91: สูงมาก | O91: 1487.7376 | P91: 87.081262 | Q91: 114.55665 | R91: 15 | S91: 6 | T91: 10 | U91: 16 | V91: 16 | W91: 8 | X91: 16-16-8 | Y91: 50 | Z91: 21 | AA91: 7 | AB91: 18 | AC91: 21-7-18 | AD91: 50 | AE91: 18.5 | AF91: 11.5 | AG91: 13
A92: 183 | B92: 59 | C92: ไร่หนองกระทุ่ม2 | D92: 1001 | E92: =VLOOKUP(D92,รายแปลง!E:G,3,FALSE) -> 906133 | F92: 8.15 | G92: ด่างอ่อน | H92: 0.11 | I92: 1.457 | J92: ต่ำ | K92: 143.8 | L92: สูง | M92: 171.95 | N92: สูงมาก | Q92: 83.7 | R92: 15 | S92: 6 | T92: 10 | U92: 16 | V92: 8 | W92: 8 | X92: 16-8-8 | Y92: 50 | Z92: 21 | AA92: 7 | AB92: 18 | AC92: 21-7-18 | AD92: 50 | AE92: 18.5 | AF92: 7.5 | AG92: 13
A93: 184 | B93: 59 | C93: ไร่หนองกระทุ่ม2 | D93: 1002 | E93: =VLOOKUP(D93,รายแปลง!E:G,3,FALSE) -> 906130 | F93: 8.17 | G93: ด่างอ่อน | H93: 0.097 | I93: 1.059 | J93: ต่ำ | K93: 53.93 | L93: สูง | M93: 46.78 | N93: ต่ำ | Q93: 114.14 | R93: 15 | S93: 6 | T93: 15 | U93: 16 | V93: 8 | W93: 8 | X93: 16-8-8 | Y93: 50 | Z93: 20 | AA93: 8 | AB93: 20 | AC93: 20-8-20 | AD93: 50 | AE93: 18 | AF93: 8 | AG93: 14
A94: 185 | B94: 59 | C94: ไร่หนองกระทุ่ม2 | D94: 1007 | E94: =VLOOKUP(D94,รายแปลง!E:G,3,FALSE) -> 906131 | F94: 8.25 | G94: ด่างอ่อน | H94: 0.097 | I94: 1.073 | J94: ต่ำ | K94: 92.25 | L94: สูง | M94: 156.98 | N94: สูงมาก | Q94: 111.34 | R94: 15 | S94: 6 | T94: 10 | U94: 16 | V94: 8 | W94: 8 | X94: 16-8-8 | Y94: 50 | Z94: 21 | AA94: 7 | AB94: 18 | AC94: 21-7-18 | AD94: 50 | AE94: 18.5 | AF94: 7.5 | AG94: 13
A95: 186 | B95: 59 | C95: ไร่หนองกระทุ่ม2 | D95: 1008 | E95: =VLOOKUP(D95,รายแปลง!E:G,3,FALSE) -> 906132 | F95: 8.05 | G95: ด่างอ่อน | H95: 0.13 | I95: 1.311 | J95: ต่ำ | K95: 22.84 | L95: ปานกลาง | M95: 158.14 | N95: สูงมาก | Q95: 97.95 | R95: 15 | S95: 9 | T95: 10 | U95: 16 | V95: 16 | W95: 8 | X95: 16-16-8 | Y95: 50 | Z95: 21 | AA95: 7 | AB95: 18 | AC95: 21-7-18 | AD95: 50 | AE95: 18.5 | AF95: 11.5 | AG95: 13
A96: 187 | B96: 59 | C96: ไร่หนองกระทุ่ม2 | D96: 1015 | E96: =VLOOKUP(D96,รายแปลง!E:G,3,FALSE) -> 906134 | F96: 8.32 | G96: ด่างอ่อน | H96: 0.11 | I96: 1.033 | J96: ต่ำ | K96: 50.7 | L96: สูง | M96: 116.22 | N96: สูง | Q96: 91.74 | R96: 15 | S96: 6 | T96: 10 | U96: 16 | V96: 8 | W96: 8 | X96: 16-8-8 | Y96: 50 | Z96: 21 | AA96: 7 | AB96: 18 | AC96: 21-7-18 | AD96: 50 | AE96: 18.5 | AF96: 7.5 | AG96: 13
A97: 188 | B97: 59 | C97: ไร่หนองกระทุ่ม2 | D97: 1017 | E97: =VLOOKUP(D97,รายแปลง!E:G,3,FALSE) -> 906135 | F97: 8.15 | G97: ด่างอ่อน | H97: 0.096 | I97: 1.263 | J97: ต่ำ | K97: 105.87 | L97: สูง | M97: 47.04 | N97: ต่ำ | Q97: 83.43 | R97: 15 | S97: 6 | T97: 15 | U97: 16 | V97: 8 | W97: 8 | X97: 16-8-8 | Y97: 50 | Z97: 20 | AA97: 8 | AB97: 20 | AC97: 20-8-20 | AD97: 50 | AE97: 18 | AF97: 8 | AG97: 14
A98: 189 | B98: 59 | C98: ไร่หนองกระทุ่ม2 | D98: 1019 | E98: =VLOOKUP(D98,รายแปลง!E:G,3,FALSE) -> 906139 | F98: 7.97 | G98: ด่างอ่อน | H98: 0.075 | I98: 1.035 | J98: ต่ำ | K98: 17.82 | L98: ต่ำ | M98: 46.84 | N98: ต่ำ | Q98: 97.19 | R98: 15 | S98: 9 | T98: 15 | U98: 16 | V98: 16 | W98: 8 | X98: 16-16-8 | Y98: 50 | Z98: 20 | AA98: 8 | AB98: 20 | AC98: 20-8-20 | AD98: 50 | AE98: 18 | AF98: 12 | AG98: 14
A99: 190 | B99: 59 | C99: ไร่หนองกระทุ่ม2 | D99: 1020 | E99: =VLOOKUP(D99,รายแปลง!E:G,3,FALSE) -> 906138 | F99: 7.18 | G99: ปานกลาง | H99: 0.22 | I99: 1.171 | J99: ต่ำ | K99: 252.49 | L99: สูง | M99: 55.36 | N99: ต่ำ | Q99: 69.03 | R99: 15 | S99: 6 | T99: 15 | U99: 16 | V99: 8 | W99: 8 | X99: 16-8-8 | Y99: 50 | Z99: 20 | AA99: 8 | AB99: 20 | AC99: 20-8-20 | AD99: 50 | AE99: 18 | AF99: 8 | AG99: 14
...

Sheet วิเคราะห์ดินปี68
Q1: ความต้องการธาตุอาหาร (กก./ไร่) | W1: คำแนะนำการใช้ปุ๋ยสำหรับอ้อยปลูก | AD1: คำแนะนำการใช้ปุ๋ยสำหรับอ้อยตอ
E2: แปลงพักดิน ปี 2568/69 เพื่อปลูกอ้อยตุลาคม ปี 2569/70 | Q2: อ้อยปลูก | T2: อ้อยตอ | W2: สูตรปุ๋ยรองพื้น | X2: อัตรา | Y2: สูตรปุ๋ยแต่งหน้า | Z2: อัตรา | AA2: ธาตุอาหารที่ได้ | AD2: สูตรปุ๋ยรองพื้น | AE2: อัตรา | AF2: สูตรปุ๋ยแต่งหน้า | AG2: อัตรา | AH2: สูตรปุ๋ยดพิ่มผลผลิต | AI2: อัตรา | AJ2: ธาตุอาหารที่ได้
A3: ปี | B3: ลำดับ | C3: รหัสตัวอย่าง | D3: ชื่อผู้ส่งตัวอย่าง | E3: สถานที่เก็บตัวอย่าง | F3: รหัสแปลง | G3: pH | H3: ระดับ | I3: EC (mS/cm) | J3: ระดับ | K3: OM (%) | L3: ระดับ | M3: P (mg/kg) | N3: ระดับ | O3: K (mg/kg) | P3: ระดับ | Q3: N | R3: P | S3: K | T3: N | U3: P | V3: K | X3: (กก./ไร่) | Z3: (กก./ไร่) | AA3: N | AB3: P | AC3: K | AE3: (กก./ไร่) | AG3: (กก./ไร่) | AI3: (กก./ไร่) | AJ3: N | AK3: P | AL3: K
A4: 68 | B4: 1 | C4: 6826Mar01 | D4: ธวุธ | E4: หนองแก | F4: 928109 | G4: 6.9 | H4: ปานกลาง | I4: 0.06612 | J4: ไม่เค็ม | K4: 0.8268478 | L4: ต่ำ | M4: 10.42008 | N4: ต่ำ | O4: 55 | P4: ต่ำ | Q4: 18 | R4: 12 | S4: 15 | T4: 24 | U4: 12 | V4: 24 | W4: 16-16-8 | X4: 50 | Y4: 20-8-20 | Z4: 50 | AA4: 18 | AB4: 12 | AC4: 14 | AD4: 16-16-8 | AE4: 50 | AF4: 14-7-35 | AG4: 50 | AH4: 46-0-0 | AI4: 30 | AJ4: 21.3 | AK4: 11.5 | AL4: 21.5
A5: 68 | B5: 2 | C5: 6826Mar02 | D5: ธวุธ | E5: หนองแก | F5: 928107 | G5: 6.7 | H5: ปานกลาง | I5: 0.07523 | J5: ไม่เค็ม | K5: 1.5351648 | L5: ต่ำ | M5: 13.427334 | N5: ต่ำ | O5: 58 | P5: ต่ำ | Q5: 15 | R5: 12 | S5: 15 | T5: 18 | U5: 12 | V5: 24 | W5: 16-16-8 | X5: 50 | Y5: 21-7-18 | Z5: 50 | AA5: 18.5 | AB5: 11.5 | AC5: 13 | AD5: 20-8-8 | AE5: 50 | AF5: 14-6-28 | AG5: 50 | AH5: 46-0-0 | AI5: 0 | AJ5: 17 | AK5: 7 | AL5: 18
A6: 68 | B6: 3 | C6: 6826Mar03 | D6: ธวุธ | E6: หนองแก | F6: 928136 | G6: 7.43 | H6: ด่างอ่อน | I6: 0.1955 | J6: ไม่เค็ม | K6: 0.16145912 | L6: ต่ำมาก | M6: 21.109291 | N6: ปานกลาง | O6: 40 | P6: ต่ำ | Q6: 18 | R6: 9 | S6: 15 | T6: 24 | U6: 9 | V6: 24 | W6: 16-16-8 | X6: 50 | Y6: 20-8-20 | Z6: 50 | AA6: 18 | AB6: 12 | AC6: 14 | AD6: 16-16-8 | AE6: 50 | AF6: 14-7-35 | AG6: 50 | AH6: 46-0-0 | AI6: 30 | AJ6: 21.3 | AK6: 11.5 | AL6: 21.5
A7: 68 | B7: 4 | C7: 6826Mar04 | D7: ธวุธ | E7: หนองแก | F7: 928111 | G7: 6.6 | H7: ปานกลาง | I7: 0.07075 | J7: ไม่เค็ม | K7: 0.61220629 | L7: ต่ำ | M7: 19.365785 | N7: ต่ำ | O7: 200 | P7: สูงมาก | Q7: 18 | R7: 9 | S7: 10 | T7: 24 | U7: 9 | V7: 12 | W7: 16-16-8 | X7: 50 | Y7: 21-7-18 | Z7: 50 | AA7: 18.5 | AB7: 11.5 | AC7: 13 | AD7: 20-8-8 | AE7: 50 | AF7: 14-6-28 | AG7: 50 | AH7: 46-0-0 | AI7: 0 | AJ7: 17 | AK7: 7 | AL7: 18
A8: 68 | B8: 5 | C8: 6826Mar05 | D8: ธวุธ | E8: หนองแก | F8: 928119 | G8: 6.07 | H8: ปานกลาง | I8: 0.03799 | J8: ไม่เค็ม | K8: 1.4 | L8: ต่ำ | M8: 20.752399 | N8: ปานกลาง | O8: 140 | P8: สูงมาก | Q8: 15 | R8: 9 | S8: 10 | T8: 18 | U8: 9 | V8: 12 | W8: 16-8-8 | X8: 50 | Y8: 15-7-18 | Z8: 50 | AA8: 15.5 | AB8: 7.5 | AC8: 13 | AD8: 16-8-8 | AE8: 50 | AF8: 15-7-18 | AG8: 50 | AH8: 46-0-0 | AI8: 0 | AJ8: 15.5 | AK8: 7.5 | AL8: 13
A9: 68 | B9: 6 | C9: 6826Mar06 | D9: ธวุธ | E9: หนองแก | F9: 928127 | G9: 6.32 | H9: ปานกลาง | I9: 0.0539 | J9: ไม่เค็ม | K9: 1.5351648 | L9: ต่ำ | M9: 12.169436 | N9: ต่ำ | O9: 80 | P9: ปานกลาง | Q9: 15 | R9: 12 | S9: 12 | T9: 18 | U9: 12 | V9: 18 | W9: 16-16-8 | X9: 50 | Y9: 21-7-18 | Z9: 50 | AA9: 18.5 | AB9: 11.5 | AC9: 13 | AD9: 20-8-8 | AE9: 50 | AF9: 14-6-28 | AG9: 50 | AH9: 46-0-0 | AI9: 0 | AJ9: 17 | AK9: 7 | AL9: 18
A10: 68 | B10: 7 | C10: 6826Mar07 | D10: ธวุธ | E10: หนองแก | F10: 928135 | G10: 6.71 | H10: ปานกลาง | I10: 0.1181 | J10: ไม่เค็ม | K10: 0.032674214 | L10: ต่ำ | M10: 8.1207582 | N10: ต่ำมาก | O10: 55 | P10: ต่ำ | Q10: 18 | R10: 12 | S10: 15 | T10: 24 | U10: 12 | V10: 24 | W10: 16-16-8 | X10: 50 | Y10: 20-8-20 | Z10: 50 | AA10: 18 | AB10: 12 | AC10: 14 | AD10: 16-16-8 | AE10: 50 | AF10: 14-7-35 | AG10: 50 | AH10: 46-0-0 | AI10: 30 | AJ10: 21.3 | AK10: 11.5 | AL10: 21.5
A11: 68 | B11: 8 | C11: 6826Mar08 | D11: ธวุธ | E11: หนองแก | F11: 928141 | G11: 5.53 | H11: ปานกลาง | I11: 0.05648 | J11: ไม่เค็ม | K11: 1.5351648 | L11: ต่ำ | M11: 10.601451 | N11: ต่ำ | O11: 57 | P11: ต่ำ | Q11: 15 | R11: 12 | S11: 15 | T11: 18 | U11: 12 | V11: 24 | W11: 16-16-8 | X11: 50 | Y11: 21-7-18 | Z11: 50 | AA11: 18.5 | AB11: 11.5 | AC11: 13 | AD11: 20-8-8 | AE11: 50 | AF11: 14-6-28 | AG11: 50 | AH11: 46-0-0 | AI11: 0 | AJ11: 17 | AK11: 7 | AL11: 18
A12: 68 | B12: 9 | C12: 6826Mar09 | D12: บรรจบ | E12: เขาประทุน | F12: 917123 | G12: 5.31 | H12: กรดจัด | I12: 0.04732 | J12: ไม่เค็ม | K12: 1.5137006 | L12: ต่ำ | M12: 11.250878 | N12: ต่ำ | O12: 56 | P12: ต่ำ | Q12: 15 | R12: 12 | S12: 15 | T12: 18 | U12: 12 | V12: 24 | W12: 16-16-8 | X12: 50 | Y12: 21-7-18 | Z12: 50 | AA12: 18.5 | AB12: 11.5 | AC12: 13 | AD12: 20-8-8 | AE12: 50 | AF12: 14-6-28 | AG12: 50 | AH12: 46-0-0 | AI12: 0 | AJ12: 17 | AK12: 7 | AL12: 18
A13: 68 | B13: 10 | C13: 6826Mar10 | D13: บรรจบ | E13: เขาประทุน | F13: 917106 | G13: 6.02 | H13: ปานกลาง | I13: 0.1363 | J13: ไม่เค็ม | K13: 0.39756478 | L13: ต่ำ | M13: 15.486777 | N13: ต่ำ | O13: 10 | P13: ต่ำมาก | Q13: 18 | R13: 9 | S13: 15 | T13: 24 | U13: 9 | V13: 24 | W13: 16-16-8 | X13: 50 | Y13: 20-8-20 | Z13: 50 | AA13: 18 | AB13: 12 | AC13: 14 | AD13: 16-16-8 | AE13: 50 | AF13: 14-7-35 | AG13: 50 | AH13: 46-0-0 | AI13: 30 | AJ13: 21.3 | AK13: 11.5 | AL13: 21.5
A14: 68 | B14: 11 | C14: 6826Mar11 | D14: บรรจบ | E14: เขาประทุน | F14: 917118 | G14: 6.01 | H14: ปานกลาง | I14: 0.08322 | J14: ไม่เค็ม | K14: 1.6424855 | L14: ปานกลาง | M14: 20.635385 | N14: ปานกลาง | O14: 180 | P14: สูงมาก | Q14: 15 | R14: 9 | S14: 10 | T14: 18 | U14: 9 | V14: 12 | W14: 16-8-8 | X14: 50 | Y14: 15-7-18 | Z14: 50 | AA14: 15.5 | AB14: 7.5 | AC14: 13 | AD14: 16-8-8 | AE14: 50 | AF14: 15-7-18 | AG14: 50 | AH14: 46-0-0 | AI14: 0 | AJ14: 15.5 | AK14: 7.5 | AL14: 13
A15: 68 | B15: 12 | C15: 6826Mar12 | D15: บรรจบ | E15: เขาประทุน | F15: 917114 | G15: 6.91 | H15: ปานกลาง | I15: 0.07136 | J15: ไม่เค็ม | K15: 1.2561308 | L15: ต่ำ | M15: 16.1 | N15: ต่ำ | O15: 180 | P15: สูงมาก | Q15: 15 | R15: 9 | S15: 10 | T15: 18 | U15: 9 | V15: 12 | W15: 16-16-8 | X15: 50 | Y15: 20-8-20 | Z15: 50 | AA15: 18 | AB15: 12 | AC15: 14 | AD15: 16-16-8 | AE15: 50 | AF15: 14-7-35 | AG15: 50 | AH15: 46-0-0 | AI15: 30 | AJ15: 21.3 | AK15: 11.5 | AL15: 21.5
... A116: 68 | B116: 113 | C116: 6826Mar113 | D116: ญาโนภาส | E116: ลำอีซู | F116: 920109 | G116: 6.26 | H116: ปานกลาง | I116: 0.03553 | J116: ไม่เค็ม | K116: 0.48414591 | L116: ต่ำ | M116: 4.7000546 | N116: ขาดรุนแรง | O116: 212.8 | P116: สูงมาก | Q116: 18 | R116: 12 | S116: 10 | T116: 24 | U116: 12 | V116: 12 | W116: 16-16-8 | X116: 50 | Y116: 21-7-18 | Z116: 50 | AA116: 18.5 | AB116: 11.5 | AC116: 13 | AD116: 20-8-8 | AE116: 50 | AF116: 14-6-28 | AG116: 50 | AH116: 46-0-0 | AI116: 0 | AJ116: 17 | AK116: 7 | AL116: 18
F117: เฉลี่ย | G117: 6.8763422 | H117: ปานกลาง | I117: 0.12254093 | J117: ไม่เค็ม | K117: 1.0301617 | L117: ต่ำ | M117: 20.134007 | N117: ปานกลาง | O117: 136.28968 | P117: สูง
G118: 6.8763422 | H118: #DIV/0! | I118: 0.12254093 | J118: #DIV/0! | K118: 1.0301617 | L118: #DIV/0! | M118: 20.134007 | N118: #DIV/0! | O118: 136.28968 | P118: #DIV/0!
G119: 6.8763422
H120: หน้าโรงงาน
G121: pH | H121: 7.56 | I121: 113
G122: OM (%) | H122: 0.77
G123: P (mg/kg) | H123: 30
G124: K (mg/kg) | H124: 136.28968
G127: กรดจัด

Sheet Sheet6
B1: ลำดับที่ (No.) | C1: เลขทะเบียนตัวอย่าง (Sample Code) | F1: Parameters and Reports (As Dried Basis)
A2: ปี | D2: ชื่อตัวอย่าง (Sample Name) | E2: แปลง | F2: pH (1:5) | G2: pH-Level | H2: EC 1:5 (dS/m) | I2: %OM-Walkely and Black | J2: OM-Level | K2: Available P (mg/kg) : Bray II Method | L2: P-Level | M2: Extractable K (mg/kg) : NH4OAc Extracted & ICP | N2: K-Level
A3: 68 | B3: 1 | C3: 3547 | D3: ไร่หนองกระทิง | E3: 926119 | F3: 6.655 | G3: ปานกลาง | H3: 0.10165 | I3: 1.963827 | J3: ปานกลาง | K3: 44.154291 | L3: สูง | M3: 91.633154 | N3: สูง
A4: 68 | B4: 2 | C4: 3548 | D4: ไร่หนองกระทิง | E4: 926120 | F4: 6.975 | G4: ปานกลาง | H4: 0.1455 | I4: 1.5615183 | J4: ปานกลาง | K4: 139.4669 | L4: สูง | M4: 226.64577 | N4: สูงมาก
A5: 68 | B5: 3 | C5: 3549 | D5: ไร่หนองกระทิง | E5: 926123 | F5: 7.225 | G5: ปานกลาง | H5: 0.1027 | I5: 1.7342053 | J5: ปานกลาง | K5: 57.139501 | L5: สูง | M5: 222.50266 | N5: สูงมาก
A6: 68 | B6: 4 | C6: 3550 | D6: ไร่หนองกระทิง | E6: 926124 | F6: 7.285 | G6: ปานกลาง | H6: 0.1165 | I6: 1.6676962 | J6: ปานกลาง | K6: 54.249128 | L6: สูง | M6: 222.42515 | N6: สูงมาก
A7: 68 | B7: 5 | C7: 3551 | D7: ไร่หนองกระทิง | E7: 926127 | F7: 6.67 | G7: ปานกลาง | H7: 0.19215 | I7: 1.6610191 | J7: ปานกลาง | K7: 8.8477237 | L7: ต่ำมาก | M7: 58.193347 | N7: ต่ำ
A8: 68 | B8: 6 | C8: 3552 | D8: ไร่หนองกระทิง | E8: 926128 | F8: 6.29 | G8: ปานกลาง | H8: 0.0741 | I8: 1.8992707 | J8: ปานกลาง | K8: 5.6690987 | L8: ขาดรุนแรง | M8: 44.778056 | N8: ต่ำ
A9: 68 | B9: 7 | C9: 3553 | D9: ไร่หนองขอน | E9: 903109 | F9: 7.605 | G9: ด่างอ่อน | H9: 0.13945 | I9: 1.295679 | J9: ต่ำ | K9: 294.65461 | L9: สูง | M9: 116.69676 | N9: สูง
A10: 68 | B10: 8 | C10: 3554 | D10: ไร่หนองขอน | E10: 903112 | F10: 7.97 | G10: ด่างอ่อน | H10: 0.1798 | I10: 1.8272262 | J10: ปานกลาง | K10: 171.14099 | L10: สูง | M10: 361.57198 | N10: สูงมาก
A11: 68 | B11: 9 | C11: 3555 | D11: ไร่หนองขอน | E11: 903113 | F11: 7.88 | G11: ด่างอ่อน | H11: 0.159 | I11: 1.2674391 | J11: ต่ำ | K11: 113.96271 | L11: สูง | M11: 304.25157 | N11: สูงมาก
A12: 68 | B12: 10 | C12: 3556 | D12: ไร่หนองขอน | E12: 903114 | F12: 7.315 | G12: ด่างอ่อน | H12: 0.10295 | I12: 1.4603601 | J12: ต่ำ | K12: 162.31249 | L12: สูง | M12: 197.51647 | N12: สูงมาก
A13: 68 | B13: 11 | C13: 3557 | D13: ไร่หนองขอน | E13: 903115 | F13: 7.775 | G13: ด่างอ่อน | H13: 0.16335 | I13: 1.8771235 | J13: ปานกลาง | K13: 118.31055 | L13: สูง | M13: 197.17353 | N13: สูงมาก
A14: 68 | B14: 12 | C14: 3558 | D14: ไร่หนองขอน | E14: 903117 | F14: 7.96 | G14: ด่างอ่อน | H14: 0.13685 | I14: 1.9364333 | J14: ปานกลาง | K14: 44.531613 | L14: สูง | M14: 126.61639 | N14: สูงมาก
... A17: 68 | B17: 15 | C17: 3561 | D17: ไร่หนองขอน | E17: 903121 | F17: 6.665 | G17: ปานกลาง | H17: 0.09145 | I17: 1.19838 | J17: ต่ำ | K17: 204.91909 | L17: สูง | M17: 23.79386 | N17: ต่ำมาก
A18: 68 | B18: 16 | C18: 3562 | D18: ไร่หนองขอน | E18: 903122 | F18: 6.755 | G18: ปานกลาง | H18: 0.086 | I18: 1.0341535 | J18: ต่ำ | K18: 237.76824 | L18: สูง | M18: non-detected | N18: ต่ำมาก
A19: 68 | B19: 17 | C19: 3563 | D19: ไร่หนองขอน | E19: 903123 | F19: 7.12 | G19: ปานกลาง | H19: 0.1027 | I19: 2.226878 | J19: ปานกลาง | K19: 166.45708 | L19: สูง | M19: 107.26264 | N19: สูง
A20: 68 | B20: 18 | C20: 3564 | D20: ไร่หนองขอน | E20: 903137 | F20: 7.665 | G20: ด่างอ่อน | H20: 0.1282 | I20: 0.60163564 | J20: ต่ำมาก | K20: 32.565122 | L20: ปานกลาง | M20: 88.246558 | N20: ปานกลาง
A21: 68 | B21: 19 | C21: 3565 | D21: ไร่หนองขอน | E21: 903138 | F21: 8.06 | G21: ด่างอ่อน | H21: 0.0794 | I21: 1.0371227 | J21: ต่ำ | K21: 144.4795 | L21: สูง | M21: 16.829214 | N21: ต่ำมาก
A22: 68 | B22: 20 | C22: 3566 | D22: ไร่หนองขอน | E22: 903141 | F22: 7.82 | G22: ด่างอ่อน | H22: 0.1073 | I22: 1.6660859 | J22: ปานกลาง | K22: 25.011946 | L22: ปานกลาง | M22: 62.715502 | N22: ปานกลาง
A23: 68 | B23: 21 | C23: 3567 | D23: ไร่หนองขอน | E23: 903145 | F23: 7.76 | G23: ด่างอ่อน | H23: 0.1637 | I23: 0.73305184 | J23: ต่ำมาก | K23: 26.93108 | L23: ปานกลาง | M23: 88.688687 | N23: ปานกลาง
A24: 68 | B24: 22 | C24: 3568 | D24: ไร่หนองขอน | E24: 903147 | F24: 7.815 | G24: ด่างอ่อน | H24: 0.11385 | I24: 0.73161173 | J24: ต่ำมาก | K24: 14.222346 | L24: ต่ำ | M24: 18.860284 | N24: ต่ำมาก
A25: 68 | B25: 23 | C25: 3569 | D25: ไร่หนองขอน | E25: 930147 | F25: 7.57 | G25: ด่างอ่อน | H25: 0.07175 | I25: 0.066509375 | J25: ต่ำมาก | K25: 353.44436 | L25: สูง | M25: non-detected | N25: ต่ำมาก
A26: 68 | B26: 24 | C26: 3570 | D26: ไร่หนองขอน | E26: 903148 | F26: 7.325 | G26: ด่างอ่อน | H26: 0.1051 | I26: 1.5255439 | J26: ต่ำ | K26: 21.440886 | L26: ปานกลาง | M26: 17.331771 | N26: ต่ำมาก
A27: 68 | B27: 25 | C27: 3571 | D27: ไร่หนองขอน | E27: 903149 | F27: 7.415 | G27: ด่างอ่อน | H27: 0.03835 | I27: 0.69907149 | J27: ต่ำมาก | K27: 14.995811 | L27: ต่ำ | M27: non-detected | N27: ต่ำมาก
A28: 68 | B28: 26 | C28: 3572 | D28: ไร่หนองขอน | E28: 903150 | F28: 7.26 | G28: ปานกลาง | H28: 0.075 | I28: 0.93482989 | J28: ต่ำมาก | K28: 45.294933 | L28: สูง | M28: 18.843638 | N28: ต่ำมาก
A29: 68 | B29: 27 | C29: 3573 | D29: ไร่หนองขอน | E29: 903151 | F29: 7.815 | G29: ด่างอ่อน | H29: 0.0429 | I29: 0.70178749 | J29: ต่ำมาก | K29: 12.43238 | L29: ต่ำ | M29: non-detected | N29: ต่ำมาก
A30: 68 | B30: 28 | C30: 3574 | D30: ไร่หนองขอน | E30: 903152 | F30: 7.33 | G30: ด่างอ่อน | H30: 0.07995 | I30: 1.09251 | J30: ต่ำ | K30: 23.803062 | L30: ปานกลาง | M30: non-detected | N30: ต่ำมาก
A31: 68 | B31: 29 | C31: 3575 | D31: ไร่หนองขอน | E31: 903153 | F31: 7.71 | G31: ด่างอ่อน | H31: 0.1716 | I31: 1.138547 | J31: ต่ำ | K31: 60.408584 | L31: สูง | M31: non-detected | N31: ต่ำมาก
A32: 68 | B32: 30 | C32: 3576 | D32: ไร่หนองขอน | E32: 903154 | F32: 7.455 | G32: ด่างอ่อน | H32: 0.1257 | I32: 1.1005801 | J32: ต่ำ | K32: 13.931826 | L32: ต่ำ | M32: 45.800931 | N32: ต่ำ
A33: 68 | B33: 31 | C33: 3577 | D33: ไร่หนองขอน | E33: 903155 | F33: 7.945 | G33: ด่างอ่อน | H33: 0.10085 | I33: 1.1284601 | J33: ต่ำ | K33: 211.53393 | L33: สูง | M33: 5.8559457 | N33: ต่ำมาก
A34: 68 | B34: 32 | C34: 3578 | D34: หนองมะค่า | E34: 913105 | F34: 7.78 | G34: ด่างอ่อน | H34: 0.0797 | I34: 1.8319516 | J34: ปานกลาง | K34: 47.881055 | L34: สูง | M34: 168.77094 | N34: สูงมาก
A35: 68 | B35: 33 | C35: 3579 | D35: หนองมะค่า | E35: 913106 | F35: 7.355 | G35: ด่างอ่อน | H35: 0.13465 | I35: 1.2951837 | J35: ต่ำ | K35: 67.877525 | L35: สูง | M35: 52.750359 | N35: ต่ำ
A36: 68 | B36: 34 | C36: 3580 | D36: หนองมะค่า | E36: 913108 | F36: 7.225 | G36: ปานกลาง | H36: 0.06505 | I36: 1.6628322 | J36: ปานกลาง | K36: 67.358436 | L36: สูง | M36: 127.12167 | N36: สูงมาก
A37: 68 | B37: 35 | C37: 3581 | D37: หนองปรือ | E37: 910107 | F37: 7.515 | G37: ด่างอ่อน | H37: 0.0608 | I37: 0.93207331 | J37: ต่ำมาก | K37: 64.614884 | L37: สูง | M37: non-detected | N37: ต่ำมาก
A38: 68 | B38: 36 | C38: 3582 | D38: หนองปรือ | E38: 910108 | F38: 7.35 | G38: ด่างอ่อน | H38: 0.0342 | I38: 0.6339814 | J38: ต่ำมาก | K38: 30.110634 | L38: ปานกลาง | M38: non-detected | N38: ต่ำมาก
A39: 68 | B39: 37 | C39: 3583 | D39: หนองปรือ | E39: 910113 | F39: 7.165 | G39: ปานกลาง | H39: 0.05975 | I39: 0.93297507 | J39: ต่ำมาก | K39: 43.824849 | L39: สูง | M39: non-detected | N39: ต่ำมาก
A40: 68 | B40: 38 | C40: 3584 | D40: หนองปรือ | E40: 910116 | F40: 7.31 | G40: ด่างอ่อน | H40: 0.0497 | I40: 0.66051396 | J40: ต่ำมาก | K40: 27.197326 | L40: ปานกลาง | M40: non-detected | N40: ต่ำมาก
A41: 68 | B41: 39 | C41: 3585 | D41: หนองปรือ | E41: 910117 | F41: 7.18 | G41: ปานกลาง | H41: 0.07265 | I41: 1.5317613 | J41: ต่ำ | K41: 12.524735 | L41: ต่ำ | M41: 56.2891 | N41: ต่ำ
A42: 68 | B42: 40 | C42: 3586 | D42: หนองปรือ | E42: 910120 | F42: 7.4 | G42: ด่างอ่อน | H42: 0.046 | I42: 1.1696107 | J42: ต่ำ | K42: 36.929431 | L42: ปานกลาง | M42: 12.85139 | N42: ต่ำมาก
...
